Workbook

Sheet Cuts Input
A1: CLOTHES INDUSTRY — CUTS INPUT SHEET
A2: Enter cut data below | 2 Product Lines | 6 Sizes (S M L XL XXL XXXL)
A4: Cut # | B4: Product Line | C4: Cut Date | D4: No. of Sheets (Layers) | E4: Pieces per Marker/Sheet | F4: S % | G4: M % | H4: L % | I4: XL % | J4: XXL % | K4: XXXL % | L4: Total Pieces
A5: 1 | B5: Line A — T-Shirt | C5: 2026-08-01 | D5: 25 | E5: 16 | F5: 15 | G5: 20 | H5: 25 | I5: 20 | J5: 12 | K5: 8 | L5: =D5*E5
A6: 2 | B6: Line A — T-Shirt | C6: 2026-08-02 | D6: 30 | E6: 16 | F6: 15 | G6: 20 | H6: 25 | I6: 20 | J6: 12 | K6: 8 | L6: =D6*E6
A7: 3 | B7: Line B — Polo Shirt | C7: 2026-08-03 | D7: 20 | E7: 18 | F7: 12 | G7: 18 | H7: 25 | I7: 22 | J7: 15 | K7: 8 | L7: =D7*E7
A8: 4 | B8: Line A — T-Shirt | C8: 2026-08-04 | D8: 28 | E8: 16 | F8: 15 | G8: 20 | H8: 25 | I8: 20 | J8: 12 | K8: 8 | L8: =D8*E8
A9: 5 | B9: Line B — Polo Shirt | C9: 2026-08-05 | D9: 22 | E9: 18 | F9: 12 | G9: 18 | H9: 25 | I9: 22 | J9: 15 | K9: 8 | L9: =D9*E9
A10: 6 | B10: Line A — T-Shirt | C10: 2026-08-06 | D10: 35 | E10: 16 | F10: 15 | G10: 20 | H10: 25 | I10: 20 | J10: 12 | K10: 8 | L10: =D10*E10
A11: 7 | B11: Line B — Polo Shirt | C11: 2026-08-07 | D11: 18 | E11: 18 | F11: 12 | G11: 18 | H11: 25 | I11: 22 | J11: 15 | K11: 8 | L11: =D11*E11
A12: 8 | B12: Line A — T-Shirt | C12: 2026-08-08 | D12: 32 | E12: 16 | F12: 15 | G12: 20 | H12: 25 | I12: 20 | J12: 12 | K12: 8 | L12: =D12*E12
A13: 9 | B13: Line B — Polo Shirt | C13: 2026-08-09 | D13: 24 | E13: 18 | F13: 12 | G13: 18 | H13: 25 | I13: 22 | J13: 15 | K13: 8 | L13: =D13*E13
A14: 10 | B14: Line A — T-Shirt | C14: 2026-08-10 | D14: 27 | E14: 16 | F14: 15 | G14: 20 | H14: 25 | I14: 20 | J14: 12 | K14: 8 | L14: =D14*E14
A15: 11 | B15: Line B — Polo Shirt | C15: 2026-08-11 | D15: 26 | E15: 18 | F15: 12 | G15: 18 | H15: 25 | I15: 22 | J15: 15 | K15: 8 | L15: =D15*E15
A16: 12 | B16: Line A — T-Shirt | C16: 2026-08-12 | D16: 30 | E16: 16 | F16: 15 | G16: 20 | H16: 25 | I16: 20 | J16: 12 | K16: 8 | L16: =D16*E16
... A18: 14 | B18: Line A — T-Shirt | C18: 2026-08-14 | D18: 34 | E18: 16 | F18: 15 | G18: 20 | H18: 25 | I18: 20 | J18: 12 | K18: 8 | L18: =D18*E18
A19: TOTAL | L19: =SUM(L5:L18)

Sheet Output by Size
A1: OUTPUT PIECES BY SIZE
A2: Calculated from Cuts Input | Pieces = Sheets × Marker × Size %
A4: Cut # | B4: Product Line | C4: Cut Date | D4: S | E4: M | F4: L | G4: XL | H4: XXL | I4: XXXL | K4: SUMMARY BY LINE
A5: 1 | B5: Line A — T-Shirt | C5: 2026-08-01 | D5: ='Cuts Input'!D5*'Cuts Input'!E5*'F5 | E5: ='Cuts Input'!D5*'Cuts Input'!E5*'G5 | F5: ='Cuts Input'!D5*'Cuts Input'!E5*'H5 | G5: ='Cuts Input'!D5*'Cuts Input'!E5*'I5 | H5: ='Cuts Input'!D5*'Cuts Input'!E5*'J5 | I5: ='Cuts Input'!D5*'Cuts Input'!E5*'K5 | K5: Product Line | L5: S | M5: M | N5: L | O5: XL | P5: XXL | Q5: XXXL | R5: Total
A6: 2 | B6: Line A — T-Shirt | C6: 2026-08-02 | D6: ='Cuts Input'!D6*'Cuts Input'!E6*'F6 | E6: ='Cuts Input'!D6*'Cuts Input'!E6*'G6 | F6: ='Cuts Input'!D6*'Cuts Input'!E6*'H6 | G6: ='Cuts Input'!D6*'Cuts Input'!E6*'I6 | H6: ='Cuts Input'!D6*'Cuts Input'!E6*'J6 | I6: ='Cuts Input'!D6*'Cuts Input'!E6*'K6 | K6: Line A — T-Shirt | L6: D5+D6+D8+D10+D12+D14+D16+D18 | M6: E5+E6+E8+E10+E12+E14+E16+E18 | N6: F5+F6+F8+F10+F12+F14+F16+F18 | O6: G5+G6+G8+G10+G12+G14+G16+G18 | P6: H5+H6+H8+H10+H12+H14+H16+H18 | Q6: I5+I6+I8+I10+I12+I14+I16+I18 | R6: =SUM(L6:Q6)
A7: 3 | B7: Line B — Polo Shirt | C7: 2026-08-03 | D7: ='Cuts Input'!D7*'Cuts Input'!E7*'F7 | E7: ='Cuts Input'!D7*'Cuts Input'!E7*'G7 | F7: ='Cuts Input'!D7*'Cuts Input'!E7*'H7 | G7: ='Cuts Input'!D7*'Cuts Input'!E7*'I7 | H7: ='Cuts Input'!D7*'Cuts Input'!E7*'J7 | I7: ='Cuts Input'!D7*'Cuts Input'!E7*'K7 | K7: Line B — Polo Shirt | L7: D7+D9+D11+D13+D15+D17 | M7: E7+E9+E11+E13+E15+E17 | N7: F7+F9+F11+F13+F15+F17 | O7: G7+G9+G11+G13+G15+G17 | P7: H7+H9+H11+H13+H15+H17 | Q7: I7+I9+I11+I13+I15+I17 | R7: =SUM(L7:Q7)
A8: 4 | B8: Line A — T-Shirt | C8: 2026-08-04 | D8: ='Cuts Input'!D8*'Cuts Input'!E8*'F8 | E8: ='Cuts Input'!D8*'Cuts Input'!E8*'G8 | F8: ='Cuts Input'!D8*'Cuts Input'!E8*'H8 | G8: ='Cuts Input'!D8*'Cuts Input'!E8*'I8 | H8: ='Cuts Input'!D8*'Cuts Input'!E8*'J8 | I8: ='Cuts Input'!D8*'Cuts Input'!E8*'K8
A9: 5 | B9: Line B — Polo Shirt | C9: 2026-08-05 | D9: ='Cuts Input'!D9*'Cuts Input'!E9*'F9 | E9: ='Cuts Input'!D9*'Cuts Input'!E9*'G9 | F9: ='Cuts Input'!D9*'Cuts Input'!E9*'H9 | G9: ='Cuts Input'!D9*'Cuts Input'!E9*'I9 | H9: ='Cuts Input'!D9*'Cuts Input'!E9*'J9 | I9: ='Cuts Input'!D9*'Cuts Input'!E9*'K9
A10: 6 | B10: Line A — T-Shirt | C10: 2026-08-06 | D10: ='Cuts Input'!D10*'Cuts Input'!E10*'F10 | E10: ='Cuts Input'!D10*'Cuts Input'!E10*'G10 | F10: ='Cuts Input'!D10*'Cuts Input'!E10*'H10 | G10: ='Cuts Input'!D10*'Cuts Input'!E10*'I10 | H10: ='Cuts Input'!D10*'Cuts Input'!E10*'J10 | I10: ='Cuts Input'!D10*'Cuts Input'!E10*'K10
A11: 7 | B11: Line B — Polo Shirt | C11: 2026-08-07 | D11: ='Cuts Input'!D11*'Cuts Input'!E11*'F11 | E11: ='Cuts Input'!D11*'Cuts Input'!E11*'G11 | F11: ='Cuts Input'!D11*'Cuts Input'!E11*'H11 | G11: ='Cuts Input'!D11*'Cuts Input'!E11*'I11 | H11: ='Cuts Input'!D11*'Cuts Input'!E11*'J11 | I11: ='Cuts Input'!D11*'Cuts Input'!E11*'K11
A12: 8 | B12: Line A — T-Shirt | C12: 2026-08-08 | D12: ='Cuts Input'!D12*'Cuts Input'!E12*'F12 | E12: ='Cuts Input'!D12*'Cuts Input'!E12*'G12 | F12: ='Cuts Input'!D12*'Cuts Input'!E12*'H12 | G12: ='Cuts Input'!D12*'Cuts Input'!E12*'I12 | H12: ='Cuts Input'!D12*'Cuts Input'!E12*'J12 | I12: ='Cuts Input'!D12*'Cuts Input'!E12*'K12
A13: 9 | B13: Line B — Polo Shirt | C13: 2026-08-09 | D13: ='Cuts Input'!D13*'Cuts Input'!E13*'F13 | E13: ='Cuts Input'!D13*'Cuts Input'!E13*'G13 | F13: ='Cuts Input'!D13*'Cuts Input'!E13*'H13 | G13: ='Cuts Input'!D13*'Cuts Input'!E13*'I13 | H13: ='Cuts Input'!D13*'Cuts Input'!E13*'J13 | I13: ='Cuts Input'!D13*'Cuts Input'!E13*'K13
A14: 10 | B14: Line A — T-Shirt | C14: 2026-08-10 | D14: ='Cuts Input'!D14*'Cuts Input'!E14*'F14 | E14: ='Cuts Input'!D14*'Cuts Input'!E14*'G14 | F14: ='Cuts Input'!D14*'Cuts Input'!E14*'H14 | G14: ='Cuts Input'!D14*'Cuts Input'!E14*'I14 | H14: ='Cuts Input'!D14*'Cuts Input'!E14*'J14 | I14: ='Cuts Input'!D14*'Cuts Input'!E14*'K14
A15: 11 | B15: Line B — Polo Shirt | C15: 2026-08-11 | D15: ='Cuts Input'!D15*'Cuts Input'!E15*'F15 | E15: ='Cuts Input'!D15*'Cuts Input'!E15*'G15 | F15: ='Cuts Input'!D15*'Cuts Input'!E15*'H15 | G15: ='Cuts Input'!D15*'Cuts Input'!E15*'I15 | H15: ='Cuts Input'!D15*'Cuts Input'!E15*'J15 | I15: ='Cuts Input'!D15*'Cuts Input'!E15*'K15
A16: 12 | B16: Line A — T-Shirt | C16: 2026-08-12 | D16: ='Cuts Input'!D16*'Cuts Input'!E16*'F16 | E16: ='Cuts Input'!D16*'Cuts Input'!E16*'G16 | F16: ='Cuts Input'!D16*'Cuts Input'!E16*'H16 | G16: ='Cuts Input'!D16*'Cuts Input'!E16*'I16 | H16: ='Cuts Input'!D16*'Cuts Input'!E16*'J16 | I16: ='Cuts Input'!D16*'Cuts Input'!E16*'K16
A17: 13 | B17: Line B — Polo Shirt | C17: 2026-08-13 | D17: ='Cuts Input'!D17*'Cuts Input'!E17*'F17 | E17: ='Cuts Input'!D17*'Cuts Input'!E17*'G17 | F17: ='Cuts Input'!D17*'Cuts Input'!E17*'H17 | G17: ='Cuts Input'!D17*'Cuts Input'!E17*'I17 | H17: ='Cuts Input'!D17*'Cuts Input'!E17*'J17 | I17: ='Cuts Input'!D17*'Cuts Input'!E17*'K17
A18: 14 | B18: Line A — T-Shirt | C18: 2026-08-14 | D18: ='Cuts Input'!D18*'Cuts Input'!E18*'F18 | E18: ='Cuts Input'!D18*'Cuts Input'!E18*'G18 | F18: ='Cuts Input'!D18*'Cuts Input'!E18*'H18 | G18: ='Cuts Input'!D18*'Cuts Input'!E18*'I18 | H18: ='Cuts Input'!D18*'Cuts Input'!E18*'J18 | I18: ='Cuts Input'!D18*'Cuts Input'!E18*'K18
A19: TOTAL | D19: =SUM(D5:D18) | E19: =SUM(E5:E18) | F19: =SUM(F5:F18) | G19: =SUM(G5:G18) | H19: =SUM(H5:H18) | I19: =SUM(I5:I18)

Sheet Timeline Diagonal
A1: PRODUCTION TIMELINE — ON-TIME DIAGONAL
A2: Diagonal = On-Time | Below Diagonal = Late | Above Diagonal = Early
A4: CUT-TO-SHIP PLAN
A5: Cut # | B5: Product Line | C5: Cut Day | D5: Planned Ship Day | E5: Actual Ship Day | F5: Status | G5: S | H5: M | I5: L | J5: XL | K5: XXL | L5: XXXL
A6: 1 | B6: Line A — T-Shirt | C6: 1 | D6: 3 | E6: 3 | F6: ON TIME | G6: ='Cuts Input'!D5*'Cuts Input'!E5*'F5' | H6: ='Cuts Input'!D5*'Cuts Input'!E5*'G5' | I6: ='Cuts Input'!D5*'Cuts Input'!E5*'H5' | J6: ='Cuts Input'!D5*'Cuts Input'!E5*'I5' | K6: ='Cuts Input'!D5*'Cuts Input'!E5*'J5' | L6: ='Cuts Input'!D5*'Cuts Input'!E5*'K5'
A7: 2 | B7: Line A — T-Shirt | C7: 2 | D7: 4 | E7: 4 | F7: ON TIME | G7: ='Cuts Input'!D6*'Cuts Input'!E6*'F6' | H7: ='Cuts Input'!D6*'Cuts Input'!E6*'G6' | I7: ='Cuts Input'!D6*'Cuts Input'!E6*'H6' | J7: ='Cuts Input'!D6*'Cuts Input'!E6*'I6' | K7: ='Cuts Input'!D6*'Cuts Input'!E6*'J6' | L7: ='Cuts Input'!D6*'Cuts Input'!E6*'K6'
A8: 3 | B8: Line B — Polo Shirt | C8: 3 | D8: 5 | E8: 5 | F8: ON TIME | G8: ='Cuts Input'!D7*'Cuts Input'!E7*'F7' | H8: ='Cuts Input'!D7*'Cuts Input'!E7*'G7' | I8: ='Cuts Input'!D7*'Cuts Input'!E7*'H7' | J8: ='Cuts Input'!D7*'Cuts Input'!E7*'I7' | K8: ='Cuts Input'!D7*'Cuts Input'!E7*'J7' | L8: ='Cuts Input'!D7*'Cuts Input'!E7*'K7'
A9: 4 | B9: Line A — T-Shirt | C9: 4 | D9: 6 | E9: 7 | F9: LATE | G9: ='Cuts Input'!D8*'Cuts Input'!E8*'F8' | H9: ='Cuts Input'!D8*'Cuts Input'!E8*'G8' | I9: ='Cuts Input'!D8*'Cuts Input'!E8*'H8' | J9: ='Cuts Input'!D8*'Cuts Input'!E8*'I8' | K9: ='Cuts Input'!D8*'Cuts Input'!E8*'J8' | L9: ='Cuts Input'!D8*'Cuts Input'!E8*'K8'
A10: 5 | B10: Line B — Polo Shirt | C10: 5 | D10: 7 | E10: 7 | F10: ON TIME | G10: ='Cuts Input'!D9*'Cuts Input'!E9*'F9' | H10: ='Cuts Input'!D9*'Cuts Input'!E9*'G9' | I10: ='Cuts Input'!D9*'Cuts Input'!E9*'H9' | J10: ='Cuts Input'!D9*'Cuts Input'!E9*'I9' | K10: ='Cuts Input'!D9*'Cuts Input'!E9*'J9' | L10: ='Cuts Input'!D9*'Cuts Input'!E9*'K9'
A11: 6 | B11: Line A — T-Shirt | C11: 6 | D11: 8 | E11: 6 | F11: EARLY | G11: ='Cuts Input'!D10*'Cuts Input'!E10*'F10' | H11: ='Cuts Input'!D10*'Cuts Input'!E10*'G10' | I11: ='Cuts Input'!D10*'Cuts Input'!E10*'H10' | J11: ='Cuts Input'!D10*'Cuts Input'!E10*'I10' | K11: ='Cuts Input'!D10*'Cuts Input'!E10*'J10' | L11: ='Cuts Input'!D10*'Cuts Input'!E10*'K10'
A12: 7 | B12: Line B — Polo Shirt | C12: 7 | D12: 9 | E12: 9 | F12: ON TIME | G12: ='Cuts Input'!D11*'Cuts Input'!E11*'F11' | H12: ='Cuts Input'!D11*'Cuts Input'!E11*'G11' | I12: ='Cuts Input'!D11*'Cuts Input'!E11*'H11' | J12: ='Cuts Input'!D11*'Cuts Input'!E11*'I11' | K12: ='Cuts Input'!D11*'Cuts Input'!E11*'J11' | L12: ='Cuts Input'!D11*'Cuts Input'!E11*'K11'
A13: 8 | B13: Line A — T-Shirt | C13: 8 | D13: 10 | E13: 10 | F13: ON TIME | G13: ='Cuts Input'!D12*'Cuts Input'!E12*'F12' | H13: ='Cuts Input'!D12*'Cuts Input'!E12*'G12' | I13: ='Cuts Input'!D12*'Cuts Input'!E12*'H12' | J13: ='Cuts Input'!D12*'Cuts Input'!E12*'I12' | K13: ='Cuts Input'!D12*'Cuts Input'!E12*'J12' | L13: ='Cuts Input'!D12*'Cuts Input'!E12*'K12'
A14: 9 | B14: Line B — Polo Shirt | C14: 9 | D14: 11 | E14: 12 | F14: LATE | G14: ='Cuts Input'!D13*'Cuts Input'!E13*'F13' | H14: ='Cuts Input'!D13*'Cuts Input'!E13*'G13' | I14: ='Cuts Input'!D13*'Cuts Input'!E13*'H13' | J14: ='Cuts Input'!D13*'Cuts Input'!E13*'I13' | K14: ='Cuts Input'!D13*'Cuts Input'!E13*'J13' | L14: ='Cuts Input'!D13*'Cuts Input'!E13*'K13'
A15: 10 | B15: Line A — T-Shirt | C15: 10 | D15: 12 | E15: 12 | F15: ON TIME | G15: ='Cuts Input'!D14*'Cuts Input'!E14*'F14' | H15: ='Cuts Input'!D14*'Cuts Input'!E14*'G14' | I15: ='Cuts Input'!D14*'Cuts Input'!E14*'H14' | J15: ='Cuts Input'!D14*'Cuts Input'!E14*'I14' | K15: ='Cuts Input'!D14*'Cuts Input'!E14*'J14' | L15: ='Cuts Input'!D14*'Cuts Input'!E14*'K14'
A16: 11 | B16: Line B — Polo Shirt | C16: 11 | D16: 13 | E16: 11 | F16: EARLY | G16: ='Cuts Input'!D15*'Cuts Input'!E15*'F15' | H16: ='Cuts Input'!D15*'Cuts Input'!E15*'G15' | I16: ='Cuts Input'!D15*'Cuts Input'!E15*'H15' | J16: ='Cuts Input'!D15*'Cuts Input'!E15*'I15' | K16: ='Cuts Input'!D15*'Cuts Input'!E15*'J15' | L16: ='Cuts Input'!D15*'Cuts Input'!E15*'K15'
A17: 12 | B17: Line A — T-Shirt | C17: 12 | D17: 14 | E17: 14 | F17: ON TIME | G17: ='Cuts Input'!D16*'Cuts Input'!E16*'F16' | H17: ='Cuts Input'!D16*'Cuts Input'!E16*'G16' | I17: ='Cuts Input'!D16*'Cuts Input'!E16*'H16' | J17: ='Cuts Input'!D16*'Cuts Input'!E16*'I16' | K17: ='Cuts Input'!D16*'Cuts Input'!E16*'J16' | L17: ='Cuts Input'!D16*'Cuts Input'!E16*'K16'
A18: 13 | B18: Line B — Polo Shirt | C18: 13 | D18: 15 | E18: 15 | F18: ON TIME | G18: ='Cuts Input'!D17*'Cuts Input'!E17*'F17' | H18: ='Cuts Input'!D17*'Cuts Input'!E17*'G17' | I18: ='Cuts Input'!D17*'Cuts Input'!E17*'H17' | J18: ='Cuts Input'!D17*'Cuts Input'!E17*'I17' | K18: ='Cuts Input'!D17*'Cuts Input'!E17*'J17' | L18: ='Cuts Input'!D17*'Cuts Input'!E17*'K17'
A19: 14 | B19: Line A — T-Shirt | C19: 14 | D19: 16 | E19: 17 | F19: LATE | G19: ='Cuts Input'!D18*'Cuts Input'!E18*'F18' | H19: ='Cuts Input'!D18*'Cuts Input'!E18*'G18' | I19: ='Cuts Input'!D18*'Cuts Input'!E18*'H18' | J19: ='Cuts Input'!D18*'Cuts Input'!E18*'I18' | K19: ='Cuts Input'!D18*'Cuts Input'!E18*'J18' | L19: ='Cuts Input'!D18*'Cuts Input'!E18*'K18'
A22: DIAGONAL MATRIX — Cut Day vs Ship Day
A23: Legend: | B23: On Time | C23: Early | D23: Late
A24: Cut \ Ship → | B24: Day 1 | C24: Day 2 | D24: Day 3 | E24: Day 4 | F24: Day 5 | G24: Day 6 | H24: Day 7 | I24: Day 8 | J24: Day 9 | K24: Day 10 | L24: Day 11 | M24: Day 12 | N24: Day 13 | O24: Day 14 | P24: Day 15 | Q24: Day 16 | R24: Day 17
A25: Day 1 | D25: C1
A26: Day 2 | E26: C2
A27: Day 3 | F27: C3
A28: Day 4 | H28: C4
A29: Day 5 | H29: C5
A30: Day 6 | G30: C6
A31: Day 7 | J31: C7
A32: Day 8 | K32: C8
A33: Day 9 | M33: C9
A34: Day 10 | M34: C10
A35: Day 11 | L35: C11
A36: Day 12 | O36: C12
A37: Day 13 | P37: C13
A38: Day 14 | R38: C14
A39: Day 15
A40: Day 16
A41: Day 17
A43: STATUS SUMMARY
A44: Status | B44: Count | C44: % of Total
...

Sheet Dashboard
A1: DASHBOARD — CLOTHES PRODUCTION
A2: 2 Product Lines | 6 Sizes | 14 Cuts | Plan vs Actual Tracking
A4: Total Cuts | C4: Total Pieces | E4: On-Time % | G4: Early % | I4: Late % | K4: Product Lines | M4: Size Range | O4: Days Scheduled
A5: ='Cuts Input'!L19 | C5: ='Cuts Input'!L19 | E5: ='Timeline Diagonal'!C45 | G5: ='Timeline Diagonal'!C46 | I5: ='Timeline Diagonal'!C47 | K5: 2 | M5: S — XXXL | O5: 14
A8: Output by Size
A9: Size | B9: Pieces
A10: S | B10: ='Output by Size'!D19
A11: M | B11: ='Output by Size'!E19
A12: L | B12: ='Output by Size'!F19
A13: XL | B13: ='Output by Size'!G19
A14: XXL | B14: ='Output by Size'!H19
A15: XXXL | B15: ='Output by Size'!I19
A18: Output by Line
A19: Line | B19: Pieces
A20: Line A — T-Shirt | B20: ='Output by Size'!K6
A21: Line B — Polo Shirt | B21: ='Output by Size'!K7
A24: Plan vs Actual (Pieces/Day)
A25: Day | B25: Planned | C25: Actual
A26: Day 1 | B26: 0 | C26: 0
A27: Day 2 | B27: 0 | C27: 0
A28: Day 3 | B28: 400 | C28: 400
A29: Day 4 | B29: 480 | C29: 480
A30: Day 5 | B30: 360 | C30: 360
A31: Day 6 | B31: 448 | C31: 560
A32: Day 7 | B32: 396 | C32: 844
A33: Day 8 | B33: 560 | C33: 0
A34: Day 9 | B34: 324 | C34: 324
A35: Day 10 | B35: 512 | C35: 512
A36: Day 11 | B36: 432 | C36: 468
A37: Day 12 | B37: 432 | C37: 864
... A42: Day 17 | B42: 0 | C42: 544
A43: On-Time Status
A44: Status | B44: Count
A45: On Time | B45: 9
A46: Early | B46: 2
A47: Late | B47: 3
